Workbook

Sheet Catalogue
A2: Catalogue (les colonnes C à J sont des colonnes techniques masquées, utilisées par les formules)
C3: Famille | D3: Finition | E3: DN1 | F3: DN2 | G3: Sous-type | H3: Temperature | I3: K | J3: Reponse | K3: Fournisseur | L3: 1ère occ. fournisseur
A4: TUBESLGA040 | B4: TUBE GALVA EN 10255 SL DN40X2.9 | C4: TUBE | D4: GALVA | E4: 40 | G4: SL | K4: TCRI / ATELIER | L4: =IF(K4="",0,IF(COUNTIF($K$4:K4,K4)=1,1,0)) -> 1
A5: TUBESLGA050 | B5: TUBE GALVA EN 10255 SL DN50X3.2 | C5: TUBE | D5: GALVA | E5: 50 | G5: SL | K5: TCRI / ATELIER | L5: =IF(K5="",0,IF(COUNTIF($K$4:K5,K5)=1,1,0)) -> 0
A6: TUBESLGA065 | B6: TUBE GALVA EN 10255 SL DN65X3.2 | C6: TUBE | D6: GALVA | E6: 65 | K6: TCRI / ATELIER | L6: =IF(K6="",0,IF(COUNTIF($K$4:K6,K6)=1,1,0)) -> 0
A7: TUBESLGA080 | B7: TUBE GALVA EN 10255 SL DN80X3.2 | C7: TUBE | D7: GALVA | E7: 80 | K7: TCRI / ATELIER | L7: =IF(K7="",0,IF(COUNTIF($K$4:K7,K7)=1,1,0)) -> 0
A8: TUBETSSGA025 | B8: TUBE GALVA EN 10255 TSS DN 25X3.2 | C8: TUBE | D8: GALVA | E8: 25 | K8: TCRI / ATELIER | L8: =IF(K8="",0,IF(COUNTIF($K$4:K8,K8)=1,1,0)) -> 0
A9: TUBETSSGA032 | B9: TUBE GALVA EN 10255 TSS DN 32X3.2 | C9: TUBE | D9: GALVA | E9: 32 | K9: TCRI / ATELIER | L9: =IF(K9="",0,IF(COUNTIF($K$4:K9,K9)=1,1,0)) -> 0
A10: TUBETSSGA040 | B10: TUBE GALVA EN 10255 TSS DN 40X3.2 | C10: TUBE | D10: GALVA | E10: 40 | G10: TSS | K10: TCRI / ATELIER | L10: =IF(K10="",0,IF(COUNTIF($K$4:K10,K10)=1,1,0)) -> 0
A11: TUBETSSGA050 | B11: TUBE GALVA EN 10255 TSS DN 50X3.6 | C11: TUBE | D11: GALVA | E11: 50 | G11: TSS | K11: TCRI / ATELIER | L11: =IF(K11="",0,IF(COUNTIF($K$4:K11,K11)=1,1,0)) -> 0
A12: TUBETSSNO025 | B12: TUBE NOIR EN 10255 TSS DN 25X3.2 | C12: TUBE | D12: NOIR | E12: 25 | K12: TCRI / ATELIER | L12: =IF(K12="",0,IF(COUNTIF($K$4:K12,K12)=1,1,0)) -> 0
A13: TUBETSSNO032 | B13: TUBE NOIR EN 10255 TSS DN 32X3.2 | C13: TUBE | D13: NOIR | E13: 32 | K13: TCRI / ATELIER | L13: =IF(K13="",0,IF(COUNTIF($K$4:K13,K13)=1,1,0)) -> 0
A14: TUBETSSNO040 | B14: TUBE NOIR EN 10255 TSS DN 40X3.2 | C14: TUBE | D14: NOIR | E14: 40 | K14: TCRI / ATELIER | L14: =IF(K14="",0,IF(COUNTIF($K$4:K14,K14)=1,1,0)) -> 0
A15: TUBETSSNO050 | B15: TUBE NOIR EN 10255 TSS DN 50X3.6 | C15: TUBE | D15: NOIR | E15: 50 | K15: TCRI / ATELIER | L15: =IF(K15="",0,IF(COUNTIF($K$4:K15,K15)=1,1,0)) -> 0
A16: TUBESLGA100 | B16: TUBE GALVA EN 10255 SL DN100X3.6 | C16: TUBE | D16: GALVA | E16: 100 | K16: TCRI / ATELIER | L16: =IF(K16="",0,IF(COUNTIF($K$4:K16,K16)=1,1,0)) -> 0
A17: TUBESLGA125 | B17: TUBE GALVA EN 10217 SL DN125X3.6 | C17: TUBE | D17: GALVA | E17: 125 | K17: TCRI / ATELIER | L17: =IF(K17="",0,IF(COUNTIF($K$4:K17,K17)=1,1,0)) -> 0
A18: TUBESLGA150 | B18: TUBE GALVA EN 10217 SL DN150 X 4.5 | C18: TUBE | D18: GALVA | E18: 150 | K18: TCRI / ATELIER | L18: =IF(K18="",0,IF(COUNTIF($K$4:K18,K18)=1,1,0)) -> 0
A19: TUBE10217NO065 | B19: TUBE NOIR EN 10217 DN 65X2.6 | C19: TUBE | D19: NOIR | E19: 65 | K19: TCRI / ATELIER | L19: =IF(K19="",0,IF(COUNTIF($K$4:K19,K19)=1,1,0)) -> 0
A20: TUBE10217NO080 | B20: TUBE NOIR EN 10217 DN 80X2.9 | C20: TUBE | D20: NOIR | E20: 80 | K20: TCRI / ATELIER | L20: =IF(K20="",0,IF(COUNTIF($K$4:K20,K20)=1,1,0)) -> 0
A21: TUBE10217NO100 | B21: TUBE NOIR EN 10217 DN 100X3.2 | C21: TUBE | D21: NOIR | E21: 100 | K21: TCRI / ATELIER | L21: =IF(K21="",0,IF(COUNTIF($K$4:K21,K21)=1,1,0)) -> 0
A22: TUBE10217NO125 | B22: TUBE NOIR EN 10217 DN 125X3.6 | C22: TUBE | D22: NOIR | E22: 125 | K22: TCRI / ATELIER | L22: =IF(K22="",0,IF(COUNTIF($K$4:K22,K22)=1,1,0)) -> 0
A23: TUBE10217NO150 | B23: TUBE NOIR EN 10217 DN 150X4 | C23: TUBE | D23: NOIR | E23: 150 | K23: TCRI / ATELIER | L23: =IF(K23="",0,IF(COUNTIF($K$4:K23,K23)=1,1,0)) -> 0
... A47: COURA90BL150 | B47: COUDE 90° RAINURE BLANC DN150 | C47: COUDE90 | D47: BLANC | E47: 150 | K47: PICON / PACK | L47: =IF(K47="",0,IF(COUNTIF($K$4:K47,K47)=1,1,0)) -> 0
A48: TESEGRAGA032 | B48: TES RAINURE GALVA DN32 | C48: TES | D48: GALVA | E48: 32 | G48: RAINURE | K48: PICON / PACK | L48: =IF(K48="",0,IF(COUNTIF($K$4:K48,K48)=1,1,0)) -> 0
A49: TESEGRAGA040 | B49: TES RAINURE GALVA DN40 | C49: TES | D49: GALVA | E49: 40 | G49: RAINURE | K49: PICON / PACK | L49: =IF(K49="",0,IF(COUNTIF($K$4:K49,K49)=1,1,0)) -> 0
A50: TESEGRAGA050 | B50: TES RAINURE GALVA DN50 | C50: TES | D50: GALVA | E50: 50 | G50: RAINURE | K50: PICON / PACK | L50: =IF(K50="",0,IF(COUNTIF($K$4:K50,K50)=1,1,0)) -> 0
A51: TESEGRAGA065 | B51: TES RAINURE GALVA DN65 | C51: TES | D51: GALVA | E51: 65 | G51: RAINURE | K51: PICON / PACK | L51: =IF(K51="",0,IF(COUNTIF($K$4:K51,K51)=1,1,0)) -> 0
A52: TESEGRAGA080 | B52: TES RAINURE GALVA DN80 | C52: TES | D52: GALVA | E52: 80 | G52: RAINURE | K52: PICON / PACK | L52: =IF(K52="",0,IF(COUNTIF($K$4:K52,K52)=1,1,0)) -> 0
A53: TESEGRAGA100 | B53: TES RAINURE GALVA DN100 | C53: TES | D53: GALVA | E53: 100 | G53: RAINURE | K53: PICON / PACK | L53: =IF(K53="",0,IF(COUNTIF($K$4:K53,K53)=1,1,0)) -> 0
A54: TESEGRAGA125 | B54: TES RAINURE GALVA DN125 | C54: TES | D54: GALVA | E54: 125 | G54: RAINURE | K54: PICON / PACK | L54: =IF(K54="",0,IF(COUNTIF($K$4:K54,K54)=1,1,0)) -> 0
A55: TESEGRAGA150 | B55: TES RAINURE GALVA DN150 | C55: TES | D55: GALVA | E55: 150 | G55: RAINURE | K55: PICON / PACK | L55: =IF(K55="",0,IF(COUNTIF($K$4:K55,K55)=1,1,0)) -> 0
A56: TESEGRARO032 | B56: TES RAINURE ROUGE DN32 | C56: TES | D56: ROUGE | E56: 32 | G56: RAINURE | K56: PICON / PACK | L56: =IF(K56="",0,IF(COUNTIF($K$4:K56,K56)=1,1,0)) -> 0
A57: TESEGRARO040 | B57: TES RAINURE ROUGE DN40 | C57: TES | D57: ROUGE | E57: 40 | G57: RAINURE | K57: PICON / PACK | L57: =IF(K57="",0,IF(COUNTIF($K$4:K57,K57)=1,1,0)) -> 0
A58: TESEGRARO050 | B58: TES RAINURE ROUGE DN50 | C58: TES | D58: ROUGE | E58: 50 | G58: RAINURE | K58: PICON / PACK | L58: =IF(K58="",0,IF(COUNTIF($K$4:K58,K58)=1,1,0)) -> 0
A59: TESEGRARO065 | B59: TES RAINURE ROUGE DN65 | C59: TES | D59: ROUGE | E59: 65 | G59: RAINURE | K59: PICON / PACK | L59: =IF(K59="",0,IF(COUNTIF($K$4:K59,K59)=1,1,0)) -> 0
... A72: TESEGRABL150 | B72: TES RAINURE BLANC DN150 | C72: TES | D72: BLANC | E72: 150 | G72: RAINURE | K72: PICON / PACK | L72: =IF(K72="",0,IF(COUNTIF($K$4:K72,K72)=1,1,0)) -> 0
A73: RACCORAGA032 | B73: RACCORD RAINURE GALVA DN32 | C73: RACCORD | D73: GALVA | E73: 32 | K73: PICON / PACK | L73: =IF(K73="",0,IF(COUNTIF($K$4:K73,K73)=1,1,0)) -> 0
A74: RACCORAGA040 | B74: RACCORD RAINURE GALVA DN40 | C74: RACCORD | D74: GALVA | E74: 40 | K74: PICON / PACK | L74: =IF(K74="",0,IF(COUNTIF($K$4:K74,K74)=1,1,0)) -> 0
A75: RACCORAGA050 | B75: RACCORD RAINURE GALVA DN50 | C75: RACCORD | D75: GALVA | E75: 50 | K75: PICON / PACK | L75: =IF(K75="",0,IF(COUNTIF($K$4:K75,K75)=1,1,0)) -> 0
A76: RACCORAGA065 | B76: RACCORD RAINURE GALVA DN65 | C76: RACCORD | D76: GALVA | E76: 65 | K76: PICON / PACK | L76: =IF(K76="",0,IF(COUNTIF($K$4:K76,K76)=1,1,0)) -> 0
...

Sheet Supports
A1: Définissez ici vos groupes de supports : nom du groupe + jusqu'à 6 composants (article + quantité par support unitaire, ex: 0,3 pour 0,3 m de tige par support).
A2: MATRICE DES GROUPES DE SUPPORTS
A3: N° | B3: Nom du groupe | C3: Composant 1 | D3: Qté/support 1 | E3: Composant 2 | F3: Qté/support 2 | G3: Composant 3 | H3: Qté/support 3 | I3: Composant 4 | J3: Qté/support 4 | K3: Composant 5 | L3: Qté/support 5 | M3: Composant 6 | N3: Qté/support 6
A4: 1 | B4: Tecner / Poire | C4: TECNER GALVA M11 | D4: 1 | E4: COLLIER POIRE (DN automatique = DN du tube) | F4: 1 | G4: TIGE FILETEE GALVA LG 1M M10 | H4: 2 | I4: ECROU GALVA M10 | J4: 2
A5: 2 | B5: Equerre / Poire / Boulon | C5: EQUERRE GRINELLEGALVA 50X50 M11 | D5: 1 | E5: COLLIER POIRE (DN automatique = DN du tube) | F5: 1 | G5: TIGE FILETEE GALVA LG 1M M10 | H5: 2 | I5: ECROU GALVA M10 | J5: 2 | K5: BOULON FILET ENTIER GALVA 10X50 | L5: 1
A6: 3 | B6: Equerre / Poire / Tirefond | C6: EQUERRE GRINELLEGALVA 50X50 M11 | D6: 1 | E6: COLLIER POIRE (DN automatique = DN du tube) | F6: 1 | G6: TIGE FILETEE GALVA LG 1M M10 | H6: 2 | I6: ECROU GALVA M10 | J6: 2 | K6: TIRE FONDS GALVA 10X60MM | L6: 1
A7: 4 | B7: Tecner / Industriel | C7: TECNER GALVA M11 | D7: 1 | E7: COLLIER INDUSTRIEL (DN automatique = DN du tube) | F7: 1 | G7: TIGE FILETEE GALVA LG 1M M10 | H7: 0.5 | I7: ECROU GALVA M10 | J7: 2
A8: 5
A9: 6
A10: 7
A11: 8
A12: 9
A13: 10
A14: 11
A15: 12
A16: 13
A17: 14
A18: 15
A19: 16
... A23: 20

Sheet SPK
C1: Cases jaunes = à saisir | RAL Raccord/RAL Tube : mettre "X" sous l'option choisie | Feuille SPK uniquement
C2: MATRICE MATERIEL SPRINKLER APSAD
C3: RAL Raccord | D3: Rouge | F3: Blanc | H3: Galva
C5: RAL Tube | D5: Galva | F5: Noir
C8: Collecteur | D8: N°1 | F8: N°2 | H8: N°3 | J8: N°4
B9: ROBINETTERIE | C9: DN tube
C10: Longueur totale (m)
C11: Nbr coudes 90°
C12: DN Collecteur (piquage)
C13: Type piquage (Rainuré/Taraudé)
B14: SUPPORTAGE | C14: N°1 - Groupe
C15: N°1 - Nb supports
C16: N°2 - Groupe
C17: N°2 - Nb supports
C18: N°3 - Groupe
C19: N°3 - Nb supports
C21: Antenne | D21: N°1 | F21: N°2 | H21: N°3 | J21: N°4
B22: ROBINETTERIE | C22: DN tube
C23: DN piquage (collecteur)
C24: Type piquage (Rainuré/Taraudé)
C25: Nbr antennes
C26: Nbr spk total
C27: Ecart entre spk (m)
C28: Nbr coudes 90°
B29: SPRINKLER | C29: Type de protection
C30: DN spk
C31: Finition spk
C32: Température spk
C33: K spk
C34: Réponse spk
C35: N°1 - Groupe
C36: N°1 - Nb supports
C37: N°2 - Groupe
C38: N°2 - Nb supports
C39: N°3 - Groupe
C40: N°3 - Nb supports
C42: Matériel divers | D42: Qté
B43: CHOIX ARTICLE
C54: Consommables | D54: Qté
C55: Kolmat (pot 360ml)
...

Sheet RIA
C1: Cases jaunes = à saisir | Tout en Galva, CPC toujours en rainuré | Case grise = non applicable
C2: MATRICE MATERIEL RIA APSAD
C4: Boucle | D4: N°1 | F4: N°2 | H4: N°3 | J4: N°4
B5: ROBINETTERIE | C5: DN tube
C6: Longueur (m)
C7: Coudes 90°
C8: TES
C9: Nbre départs (réduction depuis la boucle précédente)
B10: SUPPORTAGE | C10: N°1 - Groupe
C11: N°1 - Nb supports
C12: N°2 - Groupe
C13: N°2 - Nb supports
C14: N°3 - Groupe
C15: N°3 - Nb supports
B16: RIA | C16: RIA 33/30
C17: RIA 25/30
C19: Accessoires | D19: Qté | E19: (une seule colonne, sur tube DN de la Boucle N°1)
B20: ROBINETTERIE | C20: FAVO
C21: DEFAVO
C22: Poteau RIA tournant
C23: Vanne papillon (DN Boucle N°1)
C24: Clapet anti-retour (DN Boucle N°1)
C25: Filtre (DN Boucle N°1)
C27: Matériel divers | D27: Qté
B28: CHOIX ARTICLE
C39: Consommables | D39: Qté
C40: Kolmat (pot 360ml)
C41: Filasse (200g)
C42: Teflon
C43: Graisse Gruvlock (1kg)
C44: Peinture (Bombe Galva automatique)

Sheet Liste_Materiel
A1: Origine | B1: Code article | C1: Désignation | D1: Quantité | E1: Unité | F1: Qté totale (code) | G1: 1ère occurrence
A2: Collecteur 1 | B2: =IFERROR(INDEX(Catalogue!$A$4:$A$454,SUMPRODUCT(((Catalogue!$C$4:$C$454="TUBE")*(Catalogue!$G$4:$G$454<>"SL")*(Catalogue!$D$4:$D$454=IF(SPK!$D$6="X","GALVA",IF(SPK!$F$6="X","NOIR","")))*(Catalogue!$E$4:$E$454=(SPK!$D$9+0)))*ROW(Catalogue!$C$4:$C$454))-3),"Non trouvé - vérifier") -> Non trouvé - vérifier | C2: =IFERROR(INDEX(Catalogue!$B$4:$B$454,SUMPRODUCT(((Catalogue!$C$4:$C$454="TUBE")*(Catalogue!$G$4:$G$454<>"SL")*(Catalogue!$D$4:$D$454=IF(SPK!$D$6="X","GALVA",IF(SPK!$F$6="X","NOIR","")))*(Catalogue!$E$4:$E$454=(SPK!$D$9+0)))*ROW(Catalogue!$C$4:$C$454))-3),"") | D2: =CEILING((SPK!$D$10),6) -> 0 | E2: ml | F2: =IF(AND(B2<>"",B2<>"Non trouvé - vérifier",D2<>"",D2<>0),SUMIF($B$2:$B$244,B2,$D$2:$D$244),"") | G2: =IF(AND(B2<>"",B2<>"Non trouvé - vérifier",D2<>"",D2<>0),IF(COUNTIF($B$2:B2,B2)=1,1,0),0) -> 0
A3: Collecteur 1 | B3: =IFERROR(INDEX(Catalogue!$A$4:$A$454,SUMPRODUCT(((Catalogue!$C$4:$C$454="COUDE90")*(Catalogue!$D$4:$D$454=IF(SPK!$D$4="X","ROUGE",IF(SPK!$F$4="X","BLANC",IF(SPK!$H$4="X","GALVA",""))))*(Catalogue!$E$4:$E$454=(SPK!$D$9+0)))*ROW(Catalogue!$C$4:$C$454))-3),"Non trouvé - vérifier") -> Non trouvé - vérifier | C3: =IFERROR(INDEX(Catalogue!$B$4:$B$454,SUMPRODUCT(((Catalogue!$C$4:$C$454="COUDE90")*(Catalogue!$D$4:$D$454=IF(SPK!$D$4="X","ROUGE",IF(SPK!$F$4="X","BLANC",IF(SPK!$H$4="X","GALVA",""))))*(Catalogue!$E$4:$E$454=(SPK!$D$9+0)))*ROW(Catalogue!$C$4:$C$454))-3),"") | D3: =SPK!$D$11 -> 0 | E3: pce | F3: =IF(AND(B3<>"",B3<>"Non trouvé - vérifier",D3<>"",D3<>0),SUMIF($B$2:$B$244,B3,$D$2:$D$244),"") | G3: =IF(AND(B3<>"",B3<>"Non trouvé - vérifier",D3<>"",D3<>0),IF(COUNTIF($B$2:B3,B3)=1,1,0),0) -> 0
A4: Collecteur 1 | B4: =IFERROR(INDEX(Catalogue!$A$4:$A$454,SUMPRODUCT(((Catalogue!$C$4:$C$454="CPC")*(Catalogue!$D$4:$D$454=IF(SPK!$D$4="X","ROUGE",IF(SPK!$F$4="X","GALVA",IF(SPK!$H$4="X","GALVA",""))))*(Catalogue!$F$4:$F$454=(SPK!$D$9+0))*(Catalogue!$E$4:$E$454=(SPK!$D$12+0))*(Catalogue!$G$4:$G$454=IF(LEFT(SPK!$D$13,1)="R","RAINURE",IF(LEFT(SPK!$D$13,1)="T","TARAUDE",""))))*ROW(Catalogue!$C$4:$C$454))-3),"Non trouvé - vérifier") -> Non trouvé - vérifier | C4: =IFERROR(INDEX(Catalogue!$B$4:$B$454,SUMPRODUCT(((Catalogue!$C$4:$C$454="CPC")*(Catalogue!$D$4:$D$454=IF(SPK!$D$4="X","ROUGE",IF(SPK!$F$4="X","GALVA",IF(SPK!$H$4="X","GALVA",""))))*(Catalogue!$F$4:$F$454=(SPK!$D$9+0))*(Catalogue!$E$4:$E$454=(SPK!$D$12+0))*(Catalogue!$G$4:$G$454=IF(LEFT(SPK!$D$13,1)="R","RAINURE",IF(LEFT(SPK!$D$13,1)="T","TARAUDE",""))))*ROW(Catalogue!$C$4:$C$454))-3),"") | D4: =1 -> 1 | E4: pce | F4: =IF(AND(B4<>"",B4<>"Non trouvé - vérifier",D4<>"",D4<>0),SUMIF($B$2:$B$244,B4,$D$2:$D$244),"") | G4: =IF(AND(B4<>"",B4<>"Non trouvé - vérifier",D4<>"",D4<>0),IF(COUNTIF($B$2:B4,B4)=1,1,0),0) -> 0
A5: Collecteur 1 | B5: =IFERROR(INDEX(Catalogue!$A$4:$A$454,SUMPRODUCT(((Catalogue!$C$4:$C$454="RACCORD")*(Catalogue!$D$4:$D$454=IF(SPK!$D$4="X","ROUGE",IF(SPK!$F$4="X","BLANC",IF(SPK!$H$4="X","GALVA",""))))*(Catalogue!$E$4:$E$454=(SPK!$D$9+0)))*ROW(Catalogue!$C$4:$C$454))-3),"Non trouvé - vérifier") -> Non trouvé - vérifier | C5: =IFERROR(INDEX(Catalogue!$B$4:$B$454,SUMPRODUCT(((Catalogue!$C$4:$C$454="RACCORD")*(Catalogue!$D$4:$D$454=IF(SPK!$D$4="X","ROUGE",IF(SPK!$F$4="X","BLANC",IF(SPK!$H$4="X","GALVA",""))))*(Catalogue!$E$4:$E$454=(SPK!$D$9+0)))*ROW(Catalogue!$C$4:$C$454))-3),"") | D5: =ROUNDUP(((SPK!$D$10/6)+(SPK!$D$11*2))*1.1,0) -> 0 | E5: pce | F5: =IF(AND(B5<>"",B5<>"Non trouvé - vérifier",D5<>"",D5<>0),SUMIF($B$2:$B$244,B5,$D$2:$D$244),"") | G5: =IF(AND(B5<>"",B5<>"Non trouvé - vérifier",D5<>"",D5<>0),IF(COUNTIF($B$2:B5,B5)=1,1,0),0) -> 0
A6: Collecteur 1 - Support 1 | B6: =IF((IFERROR(INDEX(Supports!$C$4:$C$23,MATCH(SPK!$D$14,Supports!$B$4:$B$23,0)),""))="","",IF(IFERROR(INDEX(Supports!$C$4:$C$23,MATCH(SPK!$D$14,Supports!$B$4:$B$23,0)),"")="ETRIER RALLONGE (DN automatique = DN du tube)",IFERROR(INDEX(Catalogue!$A$4:$A$454,SUMPRODUCT(((Catalogue!$C$4:$C$454="ETRIER")*(Catalogue!$E$4:$E$454=(SPK!$D$9+0)))*ROW(Catalogue!$C$4:$C$454))-3),"Non trouvé - vérifier"),IF(IFERROR(INDEX(Supports!$C$4:$C$23,MATCH(SPK!$D$14,Supports!$B$4:$B$23,0)),"")="COLLIER INDUSTRIEL (DN automatique = DN du tube)",IFERROR(INDEX(Catalogue!$A$4:$A$454,SUMPRODUCT(((Catalogue!$C$4:$C$454="COLLIERINDUS")*(Catalogue!$E$4:$E$454=(SPK!$D$9+0)))*ROW(Catalogue!$C$4:$C$454))-3),"Non trouvé - vérifier"),IF(IFERROR(INDEX(Supports!$C$4:$C$23,MATCH(SPK!$D$14,Supports!$B$4:$B$23,0)),"")="COLLIER POIRE (DN automatique = DN du tube)",IFERROR(INDEX(Catalogue!$A$4:$A$454,SUMPRODUCT(((Catalogue!$C$4:$C$454="COLLIERPOIRE")*(Catalogue!$E$4:$E$454=(SPK!$D$9+0)))*ROW(Catalogue!$C$4:$C$454))-3),"Non trouvé - vérifier"),IFERROR(INDEX(Catalogue!$A$4:$A$454,MATCH(IFERROR(INDEX(Supports!$C$4:$C$23,MATCH(SPK!$D$14,Supports!$B$4:$B$23,0)),""),Catalogue!$B$4:$B$454,0)),""))))) | C6: =IF((IFERROR(INDEX(Supports!$C$4:$C$23,MATCH(SPK!$D$14,Supports!$B$4:$B$23,0)),""))="","",IF(IFERROR(INDEX(Supports!$C$4:$C$23,MATCH(SPK!$D$14,Supports!$B$4:$B$23,0)),"")="ETRIER RALLONGE (DN automatique = DN du tube)",IFERROR(INDEX(Catalogue!$B$4:$B$454,SUMPRODUCT(((Catalogue!$C$4:$C$454="ETRIER")*(Catalogue!$E$4:$E$454=(SPK!$D$9+0)))*ROW(Catalogue!$C$4:$C$454))-3),""),IF(IFERROR(INDEX(Supports!$C$4:$C$23,MATCH(SPK!$D$14,Supports!$B$4:$B$23,0)),"")="COLLIER INDUSTRIEL (DN automatique = DN du tube)",IFERROR(INDEX(Catalogue!$B$4:$B$454,SUMPRODUCT(((Catalogue!$C$4:$C$454="COLLIERINDUS")*(Catalogue!$E$4:$E$454=(SPK!$D$9+0)))*ROW(Catalogue!$C$4:$C$454))-3),""),IF(IFERROR(INDEX(Supports!$C$4:$C$23,MATCH(SPK!$D$14,Supports!$B$4:$B$23,0)),"")="COLLIER POIRE (DN automatique = DN du tube)",IFERROR(INDEX(Catalogue!$B$4:$B$454,SUMPRODUCT(((Catalogue!$C$4:$C$454="COLLIERPOIRE")*(Catalogue!$E$4:$E$454=(SPK!$D$9+0)))*ROW(Catalogue!$C$4:$C$454))-3),""),IFERROR(INDEX(Supports!$C$4:$C$23,MATCH(SPK!$D$14,Supports!$B$4:$B$23,0)),""))))) | D6: =IF((IFERROR(INDEX(Supports!$C$4:$C$23,MATCH(SPK!$D$14,Supports!$B$4:$B$23,0)),""))="","",(IFERROR(INDEX(Supports!$D$4:$D$23,MATCH(SPK!$D$14,Supports!$B$4:$B$23,0)),0))*SPK!$D$15) | E6: pce/m | F6: =IF(AND(B6<>"",B6<>"Non trouvé - vérifier",D6<>"",D6<>0),SUMIF($B$2:$B$244,B6,$D$2:$D$244),"") | G6: =IF(AND(B6<>"",B6<>"Non trouvé - vérifier",D6<>"",D6<>0),IF(COUNTIF($B$2:B6,B6)=1,1,0),0) -> 0
A7: Collecteur 1 - Support 1 | B7: =IF((IFERROR(INDEX(Supports!$E$4:$E$23,MATCH(SPK!$D$14,Supports!$B$4:$B$23,0)),""))="","",IF(IFERROR(INDEX(Supports!$E$4:$E$23,MATCH(SPK!$D$14,Supports!$B$4:$B$23,0)),"")="ETRIER RALLONGE (DN automatique = DN du tube)",IFERROR(INDEX(Catalogue!$A$4:$A$454,SUMPRODUCT(((Catalogue!$C$4:$C$454="ETRIER")*(Catalogue!$E$4:$E$454=(SPK!$D$9+0)))*ROW(Catalogue!$C$4:$C$454))-3),"Non trouvé - vérifier"),IF(IFERROR(INDEX(Supports!$E$4:$E$23,MATCH(SPK!$D$14,Supports!$B$4:$B$23,0)),"")="COLLIER INDUSTRIEL (DN automatique = DN du tube)",IFERROR(INDEX(Catalogue!$A$4:$A$454,SUMPRODUCT(((Catalogue!$C$4:$C$454="COLLIERINDUS")*(Catalogue!$E$4:$E$454=(SPK!$D$9+0)))*ROW(Catalogue!$C$4:$C$454))-3),"Non trouvé - vérifier"),IF(IFERROR(INDEX(Supports!$E$4:$E$23,MATCH(SPK!$D$14,Supports!$B$4:$B$23,0)),"")="COLLIER POIRE (DN automatique = DN du tube)",IFERROR(INDEX(Catalogue!$A$4:$A$454,SUMPRODUCT(((Catalogue!$C$4:$C$454="COLLIERPOIRE")*(Catalogue!$E$4:$E$454=(SPK!$D$9+0)))*ROW(Catalogue!$C$4:$C$454))-3),"Non trouvé - vérifier"),IFERROR(INDEX(Catalogue!$A$4:$A$454,MATCH(IFERROR(INDEX(Supports!$E$4:$E$23,MATCH(SPK!$D$14,Supports!$B$4:$B$23,0)),""),Catalogue!$B$4:$B$454,0)),""))))) | C7: =IF((IFERROR(INDEX(Supports!$E$4:$E$23,MATCH(SPK!$D$14,Supports!$B$4:$B$23,0)),""))="","",IF(IFERROR(INDEX(Supports!$E$4:$E$23,MATCH(SPK!$D$14,Supports!$B$4:$B$23,0)),"")="ETRIER RALLONGE (DN automatique = DN du tube)",IFERROR(INDEX(Catalogue!$B$4:$B$454,SUMPRODUCT(((Catalogue!$C$4:$C$454="ETRIER")*(Catalogue!$E$4:$E$454=(SPK!$D$9+0)))*ROW(Catalogue!$C$4:$C$454))-3),""),IF(IFERROR(INDEX(Supports!$E$4:$E$23,MATCH(SPK!$D$14,Supports!$B$4:$B$23,0)),"")="COLLIER INDUSTRIEL (DN automatique = DN du tube)",IFERROR(INDEX(Catalogue!$B$4:$B$454,SUMPRODUCT(((Catalogue!$C$4:$C$454="COLLIERINDUS")*(Catalogue!$E$4:$E$454=(SPK!$D$9+0)))*ROW(Catalogue!$C$4:$C$454))-3),""),IF(IFERROR(INDEX(Supports!$E$4:$E$23,MATCH(SPK!$D$14,Supports!$B$4:$B$23,0)),"")="COLLIER POIRE (DN automatique = DN du tube)",IFERROR(INDEX(Catalogue!$B$4:$B$454,SUMPRODUCT(((Catalogue!$C$4:$C$454="COLLIERPOIRE")*(Catalogue!$E$4:$E$454=(SPK!$D$9+0)))*ROW(Catalogue!$C$4:$C$454))-3),""),IFERROR(INDEX(Supports!$E$4:$E$23,MATCH(SPK!$D$14,Supports!$B$4:$B$23,0)),""))))) | D7: =IF((IFERROR(INDEX(Supports!$E$4:$E$23,MATCH(SPK!$D$14,Supports!$B$4:$B$23,0)),""))="","",(IFERROR(INDEX(Supports!$F$4:$F$23,MATCH(SPK!$D$14,Supports!$B$4:$B$23,0)),0))*SPK!$D$15) | E7: pce/m | F7: =IF(AND(B7<>"",B7<>"Non trouvé - vérifier",D7<>"",D7<>0),SUMIF($B$2:$B$244,B7,$D$2:$D$244),"") | G7: =IF(AND(B7<>"",B7<>"Non trouvé - vérifier",D7<>"",D7<>0),IF(COUNTIF($B$2:B7,B7)=1,1,0),0) -> 0
A8: Collecteur 1 - Support 1 | B8: =IF((IFERROR(INDEX(Supports!$G$4:$G$23,MATCH(SPK!$D$14,Supports!$B$4:$B$23,0)),""))="","",IF(IFERROR(INDEX(Supports!$G$4:$G$23,MATCH(SPK!$D$14,Supports!$B$4:$B$23,0)),"")="ETRIER RALLONGE (DN automatique = DN du tube)",IFERROR(INDEX(Catalogue!$A$4:$A$454,SUMPRODUCT(((Catalogue!$C$4:$C$454="ETRIER")*(Catalogue!$E$4:$E$454=(SPK!$D$9+0)))*ROW(Catalogue!$C$4:$C$454))-3),"Non trouvé - vérifier"),IF(IFERROR(INDEX(Supports!$G$4:$G$23,MATCH(SPK!$D$14,Supports!$B$4:$B$23,0)),"")="COLLIER INDUSTRIEL (DN automatique = DN du tube)",IFERROR(INDEX(Catalogue!$A$4:$A$454,SUMPRODUCT(((Catalogue!$C$4:$C$454="COLLIERINDUS")*(Catalogue!$E$4:$E$454=(SPK!$D$9+0)))*ROW(Catalogue!$C$4:$C$454))-3),"Non trouvé - vérifier"),IF(IFERROR(INDEX(Supports!$G$4:$G$23,MATCH(SPK!$D$14,Supports!$B$4:$B$23,0)),"")="COLLIER POIRE (DN automatique = DN du tube)",IFERROR(INDEX(Catalogue!$A$4:$A$454,SUMPRODUCT(((Catalogue!$C$4:$C$454="COLLIERPOIRE")*(Catalogue!$E$4:$E$454=(SPK!$D$9+0)))*ROW(Catalogue!$C$4:$C$454))-3),"Non trouvé - vérifier"),IFERROR(INDEX(Catalogue!$A$4:$A$454,MATCH(IFERROR(INDEX(Supports!$G$4:$G$23,MATCH(SPK!$D$14,Supports!$B$4:$B$23,0)),""),Catalogue!$B$4:$B$454,0)),""))))) | C8: =IF((IFERROR(INDEX(Supports!$G$4:$G$23,MATCH(SPK!$D$14,Supports!$B$4:$B$23,0)),""))="","",IF(IFERROR(INDEX(Supports!$G$4:$G$23,MATCH(SPK!$D$14,Supports!$B$4:$B$23,0)),"")="ETRIER RALLONGE (DN automatique = DN du tube)",IFERROR(INDEX(Catalogue!$B$4:$B$454,SUMPRODUCT(((Catalogue!$C$4:$C$454="ETRIER")*(Catalogue!$E$4:$E$454=(SPK!$D$9+0)))*ROW(Catalogue!$C$4:$C$454))-3),""),IF(IFERROR(INDEX(Supports!$G$4:$G$23,MATCH(SPK!$D$14,Supports!$B$4:$B$23,0)),"")="COLLIER INDUSTRIEL (DN automatique = DN du tube)",IFERROR(INDEX(Catalogue!$B$4:$B$454,SUMPRODUCT(((Catalogue!$C$4:$C$454="COLLIERINDUS")*(Catalogue!$E$4:$E$454=(SPK!$D$9+0)))*ROW(Catalogue!$C$4:$C$454))-3),""),IF(IFERROR(INDEX(Supports!$G$4:$G$23,MATCH(SPK!$D$14,Supports!$B$4:$B$23,0)),"")="COLLIER POIRE (DN automatique = DN du tube)",IFERROR(INDEX(Catalogue!$B$4:$B$454,SUMPRODUCT(((Catalogue!$C$4:$C$454="COLLIERPOIRE")*(Catalogue!$E$4:$E$454=(SPK!$D$9+0)))*ROW(Catalogue!$C$4:$C$454))-3),""),IFERROR(INDEX(Supports!$G$4:$G$23,MATCH(SPK!$D$14,Supports!$B$4:$B$23,0)),""))))) | D8: =IF((IFERROR(INDEX(Supports!$G$4:$G$23,MATCH(SPK!$D$14,Supports!$B$4:$B$23,0)),""))="","",(IFERROR(INDEX(Supports!$H$4:$H$23,MATCH(SPK!$D$14,Supports!$B$4:$B$23,0)),0))*SPK!$D$15) | E8: pce/m | F8: =IF(AND(B8<>"",B8<>"Non trouvé - vérifier",D8<>"",D8<>0),SUMIF($B$2:$B$244,B8,$D$2:$D$244),"") | G8: =IF(AND(B8<>"",B8<>"Non trouvé - vérifier",D8<>"",D8<>0),IF(COUNTIF($B$2:B8,B8)=1,1,0),0) -> 0
A9: Collecteur 1 - Support 1 | B9: =IF((IFERROR(INDEX(Supports!$I$4:$I$23,MATCH(SPK!$D$14,Supports!$B$4:$B$23,0)),""))="","",IF(IFERROR(INDEX(Supports!$I$4:$I$23,MATCH(SPK!$D$14,Supports!$B$4:$B$23,0)),"")="ETRIER RALLONGE (DN automatique = DN du tube)",IFERROR(INDEX(Catalogue!$A$4:$A$454,SUMPRODUCT(((Catalogue!$C$4:$C$454="ETRIER")*(Catalogue!$E$4:$E$454=(SPK!$D$9+0)))*ROW(Catalogue!$C$4:$C$454))-3),"Non trouvé - vérifier"),IF(IFERROR(INDEX(Supports!$I$4:$I$23,MATCH(SPK!$D$14,Supports!$B$4:$B$23,0)),"")="COLLIER INDUSTRIEL (DN automatique = DN du tube)",IFERROR(INDEX(Catalogue!$A$4:$A$454,SUMPRODUCT(((Catalogue!$C$4:$C$454="COLLIERINDUS")*(Catalogue!$E$4:$E$454=(SPK!$D$9+0)))*ROW(Catalogue!$C$4:$C$454))-3),"Non trouvé - vérifier"),IF(IFERROR(INDEX(Supports!$I$4:$I$23,MATCH(SPK!$D$14,Supports!$B$4:$B$23,0)),"")="COLLIER POIRE (DN automatique = DN du tube)",IFERROR(INDEX(Catalogue!$A$4:$A$454,SUMPRODUCT(((Catalogue!$C$4:$C$454="COLLIERPOIRE")*(Catalogue!$E$4:$E$454=(SPK!$D$9+0)))*ROW(Catalogue!$C$4:$C$454))-3),"Non trouvé - vérifier"),IFERROR(INDEX(Catalogue!$A$4:$A$454,MATCH(IFERROR(INDEX(Supports!$I$4:$I$23,MATCH(SPK!$D$14,Supports!$B$4:$B$23,0)),""),Catalogue!$B$4:$B$454,0)),""))))) | C9: =IF((IFERROR(INDEX(Supports!$I$4:$I$23,MATCH(SPK!$D$14,Supports!$B$4:$B$23,0)),""))="","",IF(IFERROR(INDEX(Supports!$I$4:$I$23,MATCH(SPK!$D$14,Supports!$B$4:$B$23,0)),"")="ETRIER RALLONGE (DN automatique = DN du tube)",IFERROR(INDEX(Catalogue!$B$4:$B$454,SUMPRODUCT(((Catalogue!$C$4:$C$454="ETRIER")*(Catalogue!$E$4:$E$454=(SPK!$D$9+0)))*ROW(Catalogue!$C$4:$C$454))-3),""),IF(IFERROR(INDEX(Supports!$I$4:$I$23,MATCH(SPK!$D$14,Supports!$B$4:$B$23,0)),"")="COLLIER INDUSTRIEL (DN automatique = DN du tube)",IFERROR(INDEX(Catalogue!$B$4:$B$454,SUMPRODUCT(((Catalogue!$C$4:$C$454="COLLIERINDUS")*(Catalogue!$E$4:$E$454=(SPK!$D$9+0)))*ROW(Catalogue!$C$4:$C$454))-3),""),IF(IFERROR(INDEX(Supports!$I$4:$I$23,MATCH(SPK!$D$14,Supports!$B$4:$B$23,0)),"")="COLLIER POIRE (DN automatique = DN du tube)",IFERROR(INDEX(Catalogue!$B$4:$B$454,SUMPRODUCT(((Catalogue!$C$4:$C$454="COLLIERPOIRE")*(Catalogue!$E$4:$E$454=(SPK!$D$9+0)))*ROW(Catalogue!$C$4:$C$454))-3),""),IFERROR(INDEX(Supports!$I$4:$I$23,MATCH(SPK!$D$14,Supports!$B$4:$B$23,0)),""))))) | D9: =IF((IFERROR(INDEX(Supports!$I$4:$I$23,MATCH(SPK!$D$14,Supports!$B$4:$B$23,0)),""))="","",(IFERROR(INDEX(Supports!$J$4:$J$23,MATCH(SPK!$D$14,Supports!$B$4:$B$23,0)),0))*SPK!$D$15) | E9: pce/m | F9: =IF(AND(B9<>"",B9<>"Non trouvé - vérifier",D9<>"",D9<>0),SUMIF($B$2:$B$244,B9,$D$2:$D$244),"") | G9: =IF(AND(B9<>"",B9<>"Non trouvé - vérifier",D9<>"",D9<>0),IF(COUNTIF($B$2:B9,B9)=1,1,0),0) -> 0
A10: Collecteur 1 - Support 1 | B10: =IF((IFERROR(INDEX(Supports!$K$4:$K$23,MATCH(SPK!$D$14,Supports!$B$4:$B$23,0)),""))="","",IF(IFERROR(INDEX(Supports!$K$4:$K$23,MATCH(SPK!$D$14,Supports!$B$4:$B$23,0)),"")="ETRIER RALLONGE (DN automatique = DN du tube)",IFERROR(INDEX(Catalogue!$A$4:$A$454,SUMPRODUCT(((Catalogue!$C$4:$C$454="ETRIER")*(Catalogue!$E$4:$E$454=(SPK!$D$9+0)))*ROW(Catalogue!$C$4:$C$454))-3),"Non trouvé - vérifier"),IF(IFERROR(INDEX(Supports!$K$4:$K$23,MATCH(SPK!$D$14,Supports!$B$4:$B$23,0)),"")="COLLIER INDUSTRIEL (DN automatique = DN du tube)",IFERROR(INDEX(Catalogue!$A$4:$A$454,SUMPRODUCT(((Catalogue!$C$4:$C$454="COLLIERINDUS")*(Catalogue!$E$4:$E$454=(SPK!$D$9+0)))*ROW(Catalogue!$C$4:$C$454))-3),"Non trouvé - vérifier"),IF(IFERROR(INDEX(Supports!$K$4:$K$23,MATCH(SPK!$D$14,Supports!$B$4:$B$23,0)),"")="COLLIER POIRE (DN automatique = DN du tube)",IFERROR(INDEX(Catalogue!$A$4:$A$454,SUMPRODUCT(((Catalogue!$C$4:$C$454="COLLIERPOIRE")*(Catalogue!$E$4:$E$454=(SPK!$D$9+0)))*ROW(Catalogue!$C$4:$C$454))-3),"Non trouvé - vérifier"),IFERROR(INDEX(Catalogue!$A$4:$A$454,MATCH(IFERROR(INDEX(Supports!$K$4:$K$23,MATCH(SPK!$D$14,Supports!$B$4:$B$23,0)),""),Catalogue!$B$4:$B$454,0)),""))))) | C10: =IF((IFERROR(INDEX(Supports!$K$4:$K$23,MATCH(SPK!$D$14,Supports!$B$4:$B$23,0)),""))="","",IF(IFERROR(INDEX(Supports!$K$4:$K$23,MATCH(SPK!$D$14,Supports!$B$4:$B$23,0)),"")="ETRIER RALLONGE (DN automatique = DN du tube)",IFERROR(INDEX(Catalogue!$B$4:$B$454,SUMPRODUCT(((Catalogue!$C$4:$C$454="ETRIER")*(Catalogue!$E$4:$E$454=(SPK!$D$9+0)))*ROW(Catalogue!$C$4:$C$454))-3),""),IF(IFERROR(INDEX(Supports!$K$4:$K$23,MATCH(SPK!$D$14,Supports!$B$4:$B$23,0)),"")="COLLIER INDUSTRIEL (DN automatique = DN du tube)",IFERROR(INDEX(Catalogue!$B$4:$B$454,SUMPRODUCT(((Catalogue!$C$4:$C$454="COLLIERINDUS")*(Catalogue!$E$4:$E$454=(SPK!$D$9+0)))*ROW(Catalogue!$C$4:$C$454))-3),""),IF(IFERROR(INDEX(Supports!$K$4:$K$23,MATCH(SPK!$D$14,Supports!$B$4:$B$23,0)),"")="COLLIER POIRE (DN automatique = DN du tube)",IFERROR(INDEX(Catalogue!$B$4:$B$454,SUMPRODUCT(((Catalogue!$C$4:$C$454="COLLIERPOIRE")*(Catalogue!$E$4:$E$454=(SPK!$D$9+0)))*ROW(Catalogue!$C$4:$C$454))-3),""),IFERROR(INDEX(Supports!$K$4:$K$23,MATCH(SPK!$D$14,Supports!$B$4:$B$23,0)),""))))) | D10: =IF((IFERROR(INDEX(Supports!$K$4:$K$23,MATCH(SPK!$D$14,Supports!$B$4:$B$23,0)),""))="","",(IFERROR(INDEX(Supports!$L$4:$L$23,MATCH(SPK!$D$14,Supports!$B$4:$B$23,0)),0))*SPK!$D$15) | E10: pce/m | F10: =IF(AND(B10<>"",B10<>"Non trouvé - vérifier",D10<>"",D10<>0),SUMIF($B$2:$B$244,B10,$D$2:$D$244),"") | G10: =IF(AND(B10<>"",B10<>"Non trouvé - vérifier",D10<>"",D10<>0),IF(COUNTIF($B$2:B10,B10)=1,1,0),0) -> 0
A11: Collecteur 1 - Support 1 | B11: =IF((IFERROR(INDEX(Supports!$M$4:$M$23,MATCH(SPK!$D$14,Supports!$B$4:$B$23,0)),""))="","",IF(IFERROR(INDEX(Supports!$M$4:$M$23,MATCH(SPK!$D$14,Supports!$B$4:$B$23,0)),"")="ETRIER RALLONGE (DN automatique = DN du tube)",IFERROR(INDEX(Catalogue!$A$4:$A$454,SUMPRODUCT(((Catalogue!$C$4:$C$454="ETRIER")*(Catalogue!$E$4:$E$454=(SPK!$D$9+0)))*ROW(Catalogue!$C$4:$C$454))-3),"Non trouvé - vérifier"),IF(IFERROR(INDEX(Supports!$M$4:$M$23,MATCH(SPK!$D$14,Supports!$B$4:$B$23,0)),"")="COLLIER INDUSTRIEL (DN automatique = DN du tube)",IFERROR(INDEX(Catalogue!$A$4:$A$454,SUMPRODUCT(((Catalogue!$C$4:$C$454="COLLIERINDUS")*(Catalogue!$E$4:$E$454=(SPK!$D$9+0)))*ROW(Catalogue!$C$4:$C$454))-3),"Non trouvé - vérifier"),IF(IFERROR(INDEX(Supports!$M$4:$M$23,MATCH(SPK!$D$14,Supports!$B$4:$B$23,0)),"")="COLLIER POIRE (DN automatique = DN du tube)",IFERROR(INDEX(Catalogue!$A$4:$A$454,SUMPRODUCT(((Catalogue!$C$4:$C$454="COLLIERPOIRE")*(Catalogue!$E$4:$E$454=(SPK!$D$9+0)))*ROW(Catalogue!$C$4:$C$454))-3),"Non trouvé - vérifier"),IFERROR(INDEX(Catalogue!$A$4:$A$454,MATCH(IFERROR(INDEX(Supports!$M$4:$M$23,MATCH(SPK!$D$14,Supports!$B$4:$B$23,0)),""),Catalogue!$B$4:$B$454,0)),""))))) | C11: =IF((IFERROR(INDEX(Supports!$M$4:$M$23,MATCH(SPK!$D$14,Supports!$B$4:$B$23,0)),""))="","",IF(IFERROR(INDEX(Supports!$M$4:$M$23,MATCH(SPK!$D$14,Supports!$B$4:$B$23,0)),"")="ETRIER RALLONGE (DN automatique = DN du tube)",IFERROR(INDEX(Catalogue!$B$4:$B$454,SUMPRODUCT(((Catalogue!$C$4:$C$454="ETRIER")*(Catalogue!$E$4:$E$454=(SPK!$D$9+0)))*ROW(Catalogue!$C$4:$C$454))-3),""),IF(IFERROR(INDEX(Supports!$M$4:$M$23,MATCH(SPK!$D$14,Supports!$B$4:$B$23,0)),"")="COLLIER INDUSTRIEL (DN automatique = DN du tube)",IFERROR(INDEX(Catalogue!$B$4:$B$454,SUMPRODUCT(((Catalogue!$C$4:$C$454="COLLIERINDUS")*(Catalogue!$E$4:$E$454=(SPK!$D$9+0)))*ROW(Catalogue!$C$4:$C$454))-3),""),IF(IFERROR(INDEX(Supports!$M$4:$M$23,MATCH(SPK!$D$14,Supports!$B$4:$B$23,0)),"")="COLLIER POIRE (DN automatique = DN du tube)",IFERROR(INDEX(Catalogue!$B$4:$B$454,SUMPRODUCT(((Catalogue!$C$4:$C$454="COLLIERPOIRE")*(Catalogue!$E$4:$E$454=(SPK!$D$9+0)))*ROW(Catalogue!$C$4:$C$454))-3),""),IFERROR(INDEX(Supports!$M$4:$M$23,MATCH(SPK!$D$14,Supports!$B$4:$B$23,0)),""))))) | D11: =IF((IFERROR(INDEX(Supports!$M$4:$M$23,MATCH(SPK!$D$14,Supports!$B$4:$B$23,0)),""))="","",(IFERROR(INDEX(Supports!$N$4:$N$23,MATCH(SPK!$D$14,Supports!$B$4:$B$23,0)),0))*SPK!$D$15) | E11: pce/m | F11: =IF(AND(B11<>"",B11<>"Non trouvé - vérifier",D11<>"",D11<>0),SUMIF($B$2:$B$244,B11,$D$2:$D$244),"") | G11: =IF(AND(B11<>"",B11<>"Non trouvé - vérifier",D11<>"",D11<>0),IF(COUNTIF($B$2:B11,B11)=1,1,0),0) -> 0
A12: Collecteur 1 - Support 2 | B12: =IF((IFERROR(INDEX(Supports!$C$4:$C$23,MATCH(SPK!$D$16,Supports!$B$4:$B$23,0)),""))="","",IF(IFERROR(INDEX(Supports!$C$4:$C$23,MATCH(SPK!$D$16,Supports!$B$4:$B$23,0)),"")="ETRIER RALLONGE (DN automatique = DN du tube)",IFERROR(INDEX(Catalogue!$A$4:$A$454,SUMPRODUCT(((Catalogue!$C$4:$C$454="ETRIER")*(Catalogue!$E$4:$E$454=(SPK!$D$9+0)))*ROW(Catalogue!$C$4:$C$454))-3),"Non trouvé - vérifier"),IF(IFERROR(INDEX(Supports!$C$4:$C$23,MATCH(SPK!$D$16,Supports!$B$4:$B$23,0)),"")="COLLIER INDUSTRIEL (DN automatique = DN du tube)",IFERROR(INDEX(Catalogue!$A$4:$A$454,SUMPRODUCT(((Catalogue!$C$4:$C$454="COLLIERINDUS")*(Catalogue!$E$4:$E$454=(SPK!$D$9+0)))*ROW(Catalogue!$C$4:$C$454))-3),"Non trouvé - vérifier"),IF(IFERROR(INDEX(Supports!$C$4:$C$23,MATCH(SPK!$D$16,Supports!$B$4:$B$23,0)),"")="COLLIER POIRE (DN automatique = DN du tube)",IFERROR(INDEX(Catalogue!$A$4:$A$454,SUMPRODUCT(((Catalogue!$C$4:$C$454="COLLIERPOIRE")*(Catalogue!$E$4:$E$454=(SPK!$D$9+0)))*ROW(Catalogue!$C$4:$C$454))-3),"Non trouvé - vérifier"),IFERROR(INDEX(Catalogue!$A$4:$A$454,MATCH(IFERROR(INDEX(Supports!$C$4:$C$23,MATCH(SPK!$D$16,Supports!$B$4:$B$23,0)),""),Catalogue!$B$4:$B$454,0)),""))))) | C12: =IF((IFERROR(INDEX(Supports!$C$4:$C$23,MATCH(SPK!$D$16,Supports!$B$4:$B$23,0)),""))="","",IF(IFERROR(INDEX(Supports!$C$4:$C$23,MATCH(SPK!$D$16,Supports!$B$4:$B$23,0)),"")="ETRIER RALLONGE (DN automatique = DN du tube)",IFERROR(INDEX(Catalogue!$B$4:$B$454,SUMPRODUCT(((Catalogue!$C$4:$C$454="ETRIER")*(Catalogue!$E$4:$E$454=(SPK!$D$9+0)))*ROW(Catalogue!$C$4:$C$454))-3),""),IF(IFERROR(INDEX(Supports!$C$4:$C$23,MATCH(SPK!$D$16,Supports!$B$4:$B$23,0)),"")="COLLIER INDUSTRIEL (DN automatique = DN du tube)",IFERROR(INDEX(Catalogue!$B$4:$B$454,SUMPRODUCT(((Catalogue!$C$4:$C$454="COLLIERINDUS")*(Catalogue!$E$4:$E$454=(SPK!$D$9+0)))*ROW(Catalogue!$C$4:$C$454))-3),""),IF(IFERROR(INDEX(Supports!$C$4:$C$23,MATCH(SPK!$D$16,Supports!$B$4:$B$23,0)),"")="COLLIER POIRE (DN automatique = DN du tube)",IFERROR(INDEX(Catalogue!$B$4:$B$454,SUMPRODUCT(((Catalogue!$C$4:$C$454="COLLIERPOIRE")*(Catalogue!$E$4:$E$454=(SPK!$D$9+0)))*ROW(Catalogue!$C$4:$C$454))-3),""),IFERROR(INDEX(Supports!$C$4:$C$23,MATCH(SPK!$D$16,Supports!$B$4:$B$23,0)),""))))) | D12: =IF((IFERROR(INDEX(Supports!$C$4:$C$23,MATCH(SPK!$D$16,Supports!$B$4:$B$23,0)),""))="","",(IFERROR(INDEX(Supports!$D$4:$D$23,MATCH(SPK!$D$16,Supports!$B$4:$B$23,0)),0))*SPK!$D$17) | E12: pce/m | F12: =IF(AND(B12<>"",B12<>"Non trouvé - vérifier",D12<>"",D12<>0),SUMIF($B$2:$B$244,B12,$D$2:$D$244),"") | G12: =IF(AND(B12<>"",B12<>"Non trouvé - vérifier",D12<>"",D12<>0),IF(COUNTIF($B$2:B12,B12)=1,1,0),0) -> 0
A13: Collecteur 1 - Support 2 | B13: =IF((IFERROR(INDEX(Supports!$E$4:$E$23,MATCH(SPK!$D$16,Supports!$B$4:$B$23,0)),""))="","",IF(IFERROR(INDEX(Supports!$E$4:$E$23,MATCH(SPK!$D$16,Supports!$B$4:$B$23,0)),"")="ETRIER RALLONGE (DN automatique = DN du tube)",IFERROR(INDEX(Catalogue!$A$4:$A$454,SUMPRODUCT(((Catalogue!$C$4:$C$454="ETRIER")*(Catalogue!$E$4:$E$454=(SPK!$D$9+0)))*ROW(Catalogue!$C$4:$C$454))-3),"Non trouvé - vérifier"),IF(IFERROR(INDEX(Supports!$E$4:$E$23,MATCH(SPK!$D$16,Supports!$B$4:$B$23,0)),"")="COLLIER INDUSTRIEL (DN automatique = DN du tube)",IFERROR(INDEX(Catalogue!$A$4:$A$454,SUMPRODUCT(((Catalogue!$C$4:$C$454="COLLIERINDUS")*(Catalogue!$E$4:$E$454=(SPK!$D$9+0)))*ROW(Catalogue!$C$4:$C$454))-3),"Non trouvé - vérifier"),IF(IFERROR(INDEX(Supports!$E$4:$E$23,MATCH(SPK!$D$16,Supports!$B$4:$B$23,0)),"")="COLLIER POIRE (DN automatique = DN du tube)",IFERROR(INDEX(Catalogue!$A$4:$A$454,SUMPRODUCT(((Catalogue!$C$4:$C$454="COLLIERPOIRE")*(Catalogue!$E$4:$E$454=(SPK!$D$9+0)))*ROW(Catalogue!$C$4:$C$454))-3),"Non trouvé - vérifier"),IFERROR(INDEX(Catalogue!$A$4:$A$454,MATCH(IFERROR(INDEX(Supports!$E$4:$E$23,MATCH(SPK!$D$16,Supports!$B$4:$B$23,0)),""),Catalogue!$B$4:$B$454,0)),""))))) | C13: =IF((IFERROR(INDEX(Supports!$E$4:$E$23,MATCH(SPK!$D$16,Supports!$B$4:$B$23,0)),""))="","",IF(IFERROR(INDEX(Supports!$E$4:$E$23,MATCH(SPK!$D$16,Supports!$B$4:$B$23,0)),"")="ETRIER RALLONGE (DN automatique = DN du tube)",IFERROR(INDEX(Catalogue!$B$4:$B$454,SUMPRODUCT(((Catalogue!$C$4:$C$454="ETRIER")*(Catalogue!$E$4:$E$454=(SPK!$D$9+0)))*ROW(Catalogue!$C$4:$C$454))-3),""),IF(IFERROR(INDEX(Supports!$E$4:$E$23,MATCH(SPK!$D$16,Supports!$B$4:$B$23,0)),"")="COLLIER INDUSTRIEL (DN automatique = DN du tube)",IFERROR(INDEX(Catalogue!$B$4:$B$454,SUMPRODUCT(((Catalogue!$C$4:$C$454="COLLIERINDUS")*(Catalogue!$E$4:$E$454=(SPK!$D$9+0)))*ROW(Catalogue!$C$4:$C$454))-3),""),IF(IFERROR(INDEX(Supports!$E$4:$E$23,MATCH(SPK!$D$16,Supports!$B$4:$B$23,0)),"")="COLLIER POIRE (DN automatique = DN du tube)",IFERROR(INDEX(Catalogue!$B$4:$B$454,SUMPRODUCT(((Catalogue!$C$4:$C$454="COLLIERPOIRE")*(Catalogue!$E$4:$E$454=(SPK!$D$9+0)))*ROW(Catalogue!$C$4:$C$454))-3),""),IFERROR(INDEX(Supports!$E$4:$E$23,MATCH(SPK!$D$16,Supports!$B$4:$B$23,0)),""))))) | D13: =IF((IFERROR(INDEX(Supports!$E$4:$E$23,MATCH(SPK!$D$16,Supports!$B$4:$B$23,0)),""))="","",(IFERROR(INDEX(Supports!$F$4:$F$23,MATCH(SPK!$D$16,Supports!$B$4:$B$23,0)),0))*SPK!$D$17) | E13: pce/m | F13: =IF(AND(B13<>"",B13<>"Non trouvé - vérifier",D13<>"",D13<>0),SUMIF($B$2:$B$244,B13,$D$2:$D$244),"") | G13: =IF(AND(B13<>"",B13<>"Non trouvé - vérifier",D13<>"",D13<>0),IF(COUNTIF($B$2:B13,B13)=1,1,0),0) -> 0
A14: Collecteur 1 - Support 2 | B14: =IF((IFERROR(INDEX(Supports!$G$4:$G$23,MATCH(SPK!$D$16,Supports!$B$4:$B$23,0)),""))="","",IF(IFERROR(INDEX(Supports!$G$4:$G$23,MATCH(SPK!$D$16,Supports!$B$4:$B$23,0)),"")="ETRIER RALLONGE (DN automatique = DN du tube)",IFERROR(INDEX(Catalogue!$A$4:$A$454,SUMPRODUCT(((Catalogue!$C$4:$C$454="ETRIER")*(Catalogue!$E$4:$E$454=(SPK!$D$9+0)))*ROW(Catalogue!$C$4:$C$454))-3),"Non trouvé - vérifier"),IF(IFERROR(INDEX(Supports!$G$4:$G$23,MATCH(SPK!$D$16,Supports!$B$4:$B$23,0)),"")="COLLIER INDUSTRIEL (DN automatique = DN du tube)",IFERROR(INDEX(Catalogue!$A$4:$A$454,SUMPRODUCT(((Catalogue!$C$4:$C$454="COLLIERINDUS")*(Catalogue!$E$4:$E$454=(SPK!$D$9+0)))*ROW(Catalogue!$C$4:$C$454))-3),"Non trouvé - vérifier"),IF(IFERROR(INDEX(Supports!$G$4:$G$23,MATCH(SPK!$D$16,Supports!$B$4:$B$23,0)),"")="COLLIER POIRE (DN automatique = DN du tube)",IFERROR(INDEX(Catalogue!$A$4:$A$454,SUMPRODUCT(((Catalogue!$C$4:$C$454="COLLIERPOIRE")*(Catalogue!$E$4:$E$454=(SPK!$D$9+0)))*ROW(Catalogue!$C$4:$C$454))-3),"Non trouvé - vérifier"),IFERROR(INDEX(Catalogue!$A$4:$A$454,MATCH(IFERROR(INDEX(Supports!$G$4:$G$23,MATCH(SPK!$D$16,Supports!$B$4:$B$23,0)),""),Catalogue!$B$4:$B$454,0)),""))))) | C14: =IF((IFERROR(INDEX(Supports!$G$4:$G$23,MATCH(SPK!$D$16,Supports!$B$4:$B$23,0)),""))="","",IF(IFERROR(INDEX(Supports!$G$4:$G$23,MATCH(SPK!$D$16,Supports!$B$4:$B$23,0)),"")="ETRIER RALLONGE (DN automatique = DN du tube)",IFERROR(INDEX(Catalogue!$B$4:$B$454,SUMPRODUCT(((Catalogue!$C$4:$C$454="ETRIER")*(Catalogue!$E$4:$E$454=(SPK!$D$9+0)))*ROW(Catalogue!$C$4:$C$454))-3),""),IF(IFERROR(INDEX(Supports!$G$4:$G$23,MATCH(SPK!$D$16,Supports!$B$4:$B$23,0)),"")="COLLIER INDUSTRIEL (DN automatique = DN du tube)",IFERROR(INDEX(Catalogue!$B$4:$B$454,SUMPRODUCT(((Catalogue!$C$4:$C$454="COLLIERINDUS")*(Catalogue!$E$4:$E$454=(SPK!$D$9+0)))*ROW(Catalogue!$C$4:$C$454))-3),""),IF(IFERROR(INDEX(Supports!$G$4:$G$23,MATCH(SPK!$D$16,Supports!$B$4:$B$23,0)),"")="COLLIER POIRE (DN automatique = DN du tube)",IFERROR(INDEX(Catalogue!$B$4:$B$454,SUMPRODUCT(((Catalogue!$C$4:$C$454="COLLIERPOIRE")*(Catalogue!$E$4:$E$454=(SPK!$D$9+0)))*ROW(Catalogue!$C$4:$C$454))-3),""),IFERROR(INDEX(Supports!$G$4:$G$23,MATCH(SPK!$D$16,Supports!$B$4:$B$23,0)),""))))) | D14: =IF((IFERROR(INDEX(Supports!$G$4:$G$23,MATCH(SPK!$D$16,Supports!$B$4:$B$23,0)),""))="","",(IFERROR(INDEX(Supports!$H$4:$H$23,MATCH(SPK!$D$16,Supports!$B$4:$B$23,0)),0))*SPK!$D$17) | E14: pce/m | F14: =IF(AND(B14<>"",B14<>"Non trouvé - vérifier",D14<>"",D14<>0),SUMIF($B$2:$B$244,B14,$D$2:$D$244),"") | G14: =IF(AND(B14<>"",B14<>"Non trouvé - vérifier",D14<>"",D14<>0),IF(COUNTIF($B$2:B14,B14)=1,1,0),0) -> 0
A15: Collecteur 1 - Support 2 | B15: =IF((IFERROR(INDEX(Supports!$I$4:$I$23,MATCH(SPK!$D$16,Supports!$B$4:$B$23,0)),""))="","",IF(IFERROR(INDEX(Supports!$I$4:$I$23,MATCH(SPK!$D$16,Supports!$B$4:$B$23,0)),"")="ETRIER RALLONGE (DN automatique = DN du tube)",IFERROR(INDEX(Catalogue!$A$4:$A$454,SUMPRODUCT(((Catalogue!$C$4:$C$454="ETRIER")*(Catalogue!$E$4:$E$454=(SPK!$D$9+0)))*ROW(Catalogue!$C$4:$C$454))-3),"Non trouvé - vérifier"),IF(IFERROR(INDEX(Supports!$I$4:$I$23,MATCH(SPK!$D$16,Supports!$B$4:$B$23,0)),"")="COLLIER INDUSTRIEL (DN automatique = DN du tube)",IFERROR(INDEX(Catalogue!$A$4:$A$454,SUMPRODUCT(((Catalogue!$C$4:$C$454="COLLIERINDUS")*(Catalogue!$E$4:$E$454=(SPK!$D$9+0)))*ROW(Catalogue!$C$4:$C$454))-3),"Non trouvé - vérifier"),IF(IFERROR(INDEX(Supports!$I$4:$I$23,MATCH(SPK!$D$16,Supports!$B$4:$B$23,0)),"")="COLLIER POIRE (DN automatique = DN du tube)",IFERROR(INDEX(Catalogue!$A$4:$A$454,SUMPRODUCT(((Catalogue!$C$4:$C$454="COLLIERPOIRE")*(Catalogue!$E$4:$E$454=(SPK!$D$9+0)))*ROW(Catalogue!$C$4:$C$454))-3),"Non trouvé - vérifier"),IFERROR(INDEX(Catalogue!$A$4:$A$454,MATCH(IFERROR(INDEX(Supports!$I$4:$I$23,MATCH(SPK!$D$16,Supports!$B$4:$B$23,0)),""),Catalogue!$B$4:$B$454,0)),""))))) | C15: =IF((IFERROR(INDEX(Supports!$I$4:$I$23,MATCH(SPK!$D$16,Supports!$B$4:$B$23,0)),""))="","",IF(IFERROR(INDEX(Supports!$I$4:$I$23,MATCH(SPK!$D$16,Supports!$B$4:$B$23,0)),"")="ETRIER RALLONGE (DN automatique = DN du tube)",IFERROR(INDEX(Catalogue!$B$4:$B$454,SUMPRODUCT(((Catalogue!$C$4:$C$454="ETRIER")*(Catalogue!$E$4:$E$454=(SPK!$D$9+0)))*ROW(Catalogue!$C$4:$C$454))-3),""),IF(IFERROR(INDEX(Supports!$I$4:$I$23,MATCH(SPK!$D$16,Supports!$B$4:$B$23,0)),"")="COLLIER INDUSTRIEL (DN automatique = DN du tube)",IFERROR(INDEX(Catalogue!$B$4:$B$454,SUMPRODUCT(((Catalogue!$C$4:$C$454="COLLIERINDUS")*(Catalogue!$E$4:$E$454=(SPK!$D$9+0)))*ROW(Catalogue!$C$4:$C$454))-3),""),IF(IFERROR(INDEX(Supports!$I$4:$I$23,MATCH(SPK!$D$16,Supports!$B$4:$B$23,0)),"")="COLLIER POIRE (DN automatique = DN du tube)",IFERROR(INDEX(Catalogue!$B$4:$B$454,SUMPRODUCT(((Catalogue!$C$4:$C$454="COLLIERPOIRE")*(Catalogue!$E$4:$E$454=(SPK!$D$9+0)))*ROW(Catalogue!$C$4:$C$454))-3),""),IFERROR(INDEX(Supports!$I$4:$I$23,MATCH(SPK!$D$16,Supports!$B$4:$B$23,0)),""))))) | D15: =IF((IFERROR(INDEX(Supports!$I$4:$I$23,MATCH(SPK!$D$16,Supports!$B$4:$B$23,0)),""))="","",(IFERROR(INDEX(Supports!$J$4:$J$23,MATCH(SPK!$D$16,Supports!$B$4:$B$23,0)),0))*SPK!$D$17) | E15: pce/m | F15: =IF(AND(B15<>"",B15<>"Non trouvé - vérifier",D15<>"",D15<>0),SUMIF($B$2:$B$244,B15,$D$2:$D$244),"") | G15: =IF(AND(B15<>"",B15<>"Non trouvé - vérifier",D15<>"",D15<>0),IF(COUNTIF($B$2:B15,B15)=1,1,0),0) -> 0
A16: Collecteur 1 - Support 2 | B16: =IF((IFERROR(INDEX(Supports!$K$4:$K$23,MATCH(SPK!$D$16,Supports!$B$4:$B$23,0)),""))="","",IF(IFERROR(INDEX(Supports!$K$4:$K$23,MATCH(SPK!$D$16,Supports!$B$4:$B$23,0)),"")="ETRIER RALLONGE (DN automatique = DN du tube)",IFERROR(INDEX(Catalogue!$A$4:$A$454,SUMPRODUCT(((Catalogue!$C$4:$C$454="ETRIER")*(Catalogue!$E$4:$E$454=(SPK!$D$9+0)))*ROW(Catalogue!$C$4:$C$454))-3),"Non trouvé - vérifier"),IF(IFERROR(INDEX(Supports!$K$4:$K$23,MATCH(SPK!$D$16,Supports!$B$4:$B$23,0)),"")="COLLIER INDUSTRIEL (DN automatique = DN du tube)",IFERROR(INDEX(Catalogue!$A$4:$A$454,SUMPRODUCT(((Catalogue!$C$4:$C$454="COLLIERINDUS")*(Catalogue!$E$4:$E$454=(SPK!$D$9+0)))*ROW(Catalogue!$C$4:$C$454))-3),"Non trouvé - vérifier"),IF(IFERROR(INDEX(Supports!$K$4:$K$23,MATCH(SPK!$D$16,Supports!$B$4:$B$23,0)),"")="COLLIER POIRE (DN automatique = DN du tube)",IFERROR(INDEX(Catalogue!$A$4:$A$454,SUMPRODUCT(((Catalogue!$C$4:$C$454="COLLIERPOIRE")*(Catalogue!$E$4:$E$454=(SPK!$D$9+0)))*ROW(Catalogue!$C$4:$C$454))-3),"Non trouvé - vérifier"),IFERROR(INDEX(Catalogue!$A$4:$A$454,MATCH(IFERROR(INDEX(Supports!$K$4:$K$23,MATCH(SPK!$D$16,Supports!$B$4:$B$23,0)),""),Catalogue!$B$4:$B$454,0)),""))))) | C16: =IF((IFERROR(INDEX(Supports!$K$4:$K$23,MATCH(SPK!$D$16,Supports!$B$4:$B$23,0)),""))="","",IF(IFERROR(INDEX(Supports!$K$4:$K$23,MATCH(SPK!$D$16,Supports!$B$4:$B$23,0)),"")="ETRIER RALLONGE (DN automatique = DN du tube)",IFERROR(INDEX(Catalogue!$B$4:$B$454,SUMPRODUCT(((Catalogue!$C$4:$C$454="ETRIER")*(Catalogue!$E$4:$E$454=(SPK!$D$9+0)))*ROW(Catalogue!$C$4:$C$454))-3),""),IF(IFERROR(INDEX(Supports!$K$4:$K$23,MATCH(SPK!$D$16,Supports!$B$4:$B$23,0)),"")="COLLIER INDUSTRIEL (DN automatique = DN du tube)",IFERROR(INDEX(Catalogue!$B$4:$B$454,SUMPRODUCT(((Catalogue!$C$4:$C$454="COLLIERINDUS")*(Catalogue!$E$4:$E$454=(SPK!$D$9+0)))*ROW(Catalogue!$C$4:$C$454))-3),""),IF(IFERROR(INDEX(Supports!$K$4:$K$23,MATCH(SPK!$D$16,Supports!$B$4:$B$23,0)),"")="COLLIER POIRE (DN automatique = DN du tube)",IFERROR(INDEX(Catalogue!$B$4:$B$454,SUMPRODUCT(((Catalogue!$C$4:$C$454="COLLIERPOIRE")*(Catalogue!$E$4:$E$454=(SPK!$D$9+0)))*ROW(Catalogue!$C$4:$C$454))-3),""),IFERROR(INDEX(Supports!$K$4:$K$23,MATCH(SPK!$D$16,Supports!$B$4:$B$23,0)),""))))) | D16: =IF((IFERROR(INDEX(Supports!$K$4:$K$23,MATCH(SPK!$D$16,Supports!$B$4:$B$23,0)),""))="","",(IFERROR(INDEX(Supports!$L$4:$L$23,MATCH(SPK!$D$16,Supports!$B$4:$B$23,0)),0))*SPK!$D$17) | E16: pce/m | F16: =IF(AND(B16<>"",B16<>"Non trouvé - vérifier",D16<>"",D16<>0),SUMIF($B$2:$B$244,B16,$D$2:$D$244),"") | G16: =IF(AND(B16<>"",B16<>"Non trouvé - vérifier",D16<>"",D16<>0),IF(COUNTIF($B$2:B16,B16)=1,1,0),0) -> 0
A17: Collecteur 1 - Support 2 | B17: =IF((IFERROR(INDEX(Supports!$M$4:$M$23,MATCH(SPK!$D$16,Supports!$B$4:$B$23,0)),""))="","",IF(IFERROR(INDEX(Supports!$M$4:$M$23,MATCH(SPK!$D$16,Supports!$B$4:$B$23,0)),"")="ETRIER RALLONGE (DN automatique = DN du tube)",IFERROR(INDEX(Catalogue!$A$4:$A$454,SUMPRODUCT(((Catalogue!$C$4:$C$454="ETRIER")*(Catalogue!$E$4:$E$454=(SPK!$D$9+0)))*ROW(Catalogue!$C$4:$C$454))-3),"Non trouvé - vérifier"),IF(IFERROR(INDEX(Supports!$M$4:$M$23,MATCH(SPK!$D$16,Supports!$B$4:$B$23,0)),"")="COLLIER INDUSTRIEL (DN automatique = DN du tube)",IFERROR(INDEX(Catalogue!$A$4:$A$454,SUMPRODUCT(((Catalogue!$C$4:$C$454="COLLIERINDUS")*(Catalogue!$E$4:$E$454=(SPK!$D$9+0)))*ROW(Catalogue!$C$4:$C$454))-3),"Non trouvé - vérifier"),IF(IFERROR(INDEX(Supports!$M$4:$M$23,MATCH(SPK!$D$16,Supports!$B$4:$B$23,0)),"")="COLLIER POIRE (DN automatique = DN du tube)",IFERROR(INDEX(Catalogue!$A$4:$A$454,SUMPRODUCT(((Catalogue!$C$4:$C$454="COLLIERPOIRE")*(Catalogue!$E$4:$E$454=(SPK!$D$9+0)))*ROW(Catalogue!$C$4:$C$454))-3),"Non trouvé - vérifier"),IFERROR(INDEX(Catalogue!$A$4:$A$454,MATCH(IFERROR(INDEX(Supports!$M$4:$M$23,MATCH(SPK!$D$16,Supports!$B$4:$B$23,0)),""),Catalogue!$B$4:$B$454,0)),""))))) | C17: =IF((IFERROR(INDEX(Supports!$M$4:$M$23,MATCH(SPK!$D$16,Supports!$B$4:$B$23,0)),""))="","",IF(IFERROR(INDEX(Supports!$M$4:$M$23,MATCH(SPK!$D$16,Supports!$B$4:$B$23,0)),"")="ETRIER RALLONGE (DN automatique = DN du tube)",IFERROR(INDEX(Catalogue!$B$4:$B$454,SUMPRODUCT(((Catalogue!$C$4:$C$454="ETRIER")*(Catalogue!$E$4:$E$454=(SPK!$D$9+0)))*ROW(Catalogue!$C$4:$C$454))-3),""),IF(IFERROR(INDEX(Supports!$M$4:$M$23,MATCH(SPK!$D$16,Supports!$B$4:$B$23,0)),"")="COLLIER INDUSTRIEL (DN automatique = DN du tube)",IFERROR(INDEX(Catalogue!$B$4:$B$454,SUMPRODUCT(((Catalogue!$C$4:$C$454="COLLIERINDUS")*(Catalogue!$E$4:$E$454=(SPK!$D$9+0)))*ROW(Catalogue!$C$4:$C$454))-3),""),IF(IFERROR(INDEX(Supports!$M$4:$M$23,MATCH(SPK!$D$16,Supports!$B$4:$B$23,0)),"")="COLLIER POIRE (DN automatique = DN du tube)",IFERROR(INDEX(Catalogue!$B$4:$B$454,SUMPRODUCT(((Catalogue!$C$4:$C$454="COLLIERPOIRE")*(Catalogue!$E$4:$E$454=(SPK!$D$9+0)))*ROW(Catalogue!$C$4:$C$454))-3),""),IFERROR(INDEX(Supports!$M$4:$M$23,MATCH(SPK!$D$16,Supports!$B$4:$B$23,0)),""))))) | D17: =IF((IFERROR(INDEX(Supports!$M$4:$M$23,MATCH(SPK!$D$16,Supports!$B$4:$B$23,0)),""))="","",(IFERROR(INDEX(Supports!$N$4:$N$23,MATCH(SPK!$D$16,Supports!$B$4:$B$23,0)),0))*SPK!$D$17) | E17: pce/m | F17: =IF(AND(B17<>"",B17<>"Non trouvé - vérifier",D17<>"",D17<>0),SUMIF($B$2:$B$244,B17,$D$2:$D$244),"") | G17: =IF(AND(B17<>"",B17<>"Non trouvé - vérifier",D17<>"",D17<>0),IF(COUNTIF($B$2:B17,B17)=1,1,0),0) -> 0
A18: Collecteur 2 | B18: =IFERROR(INDEX(Catalogue!$A$4:$A$454,SUMPRODUCT(((Catalogue!$C$4:$C$454="TUBE")*(Catalogue!$G$4:$G$454<>"SL")*(Catalogue!$D$4:$D$454=IF(SPK!$D$6="X","GALVA",IF(SPK!$F$6="X","NOIR","")))*(Catalogue!$E$4:$E$454=(SPK!$F$9+0)))*ROW(Catalogue!$C$4:$C$454))-3),"Non trouvé - vérifier") -> Non trouvé - vérifier | C18: =IFERROR(INDEX(Catalogue!$B$4:$B$454,SUMPRODUCT(((Catalogue!$C$4:$C$454="TUBE")*(Catalogue!$G$4:$G$454<>"SL")*(Catalogue!$D$4:$D$454=IF(SPK!$D$6="X","GALVA",IF(SPK!$F$6="X","NOIR","")))*(Catalogue!$E$4:$E$454=(SPK!$F$9+0)))*ROW(Catalogue!$C$4:$C$454))-3),"") | D18: =CEILING((SPK!$F$10),6) -> 0 | E18: ml | F18: =IF(AND(B18<>"",B18<>"Non trouvé - vérifier",D18<>"",D18<>0),SUMIF($B$2:$B$244,B18,$D$2:$D$244),"") | G18: =IF(AND(B18<>"",B18<>"Non trouvé - vérifier",D18<>"",D18<>0),IF(COUNTIF($B$2:B18,B18)=1,1,0),0) -> 0
A19: Collecteur 2 | B19: =IFERROR(INDEX(Catalogue!$A$4:$A$454,SUMPRODUCT(((Catalogue!$C$4:$C$454="COUDE90")*(Catalogue!$D$4:$D$454=IF(SPK!$D$4="X","ROUGE",IF(SPK!$F$4="X","BLANC",IF(SPK!$H$4="X","GALVA",""))))*(Catalogue!$E$4:$E$454=(SPK!$F$9+0)))*ROW(Catalogue!$C$4:$C$454))-3),"Non trouvé - vérifier") -> Non trouvé - vérifier | C19: =IFERROR(INDEX(Catalogue!$B$4:$B$454,SUMPRODUCT(((Catalogue!$C$4:$C$454="COUDE90")*(Catalogue!$D$4:$D$454=IF(SPK!$D$4="X","ROUGE",IF(SPK!$F$4="X","BLANC",IF(SPK!$H$4="X","GALVA",""))))*(Catalogue!$E$4:$E$454=(SPK!$F$9+0)))*ROW(Catalogue!$C$4:$C$454))-3),"") | D19: =SPK!$F$11 -> 0 | E19: pce | F19: =IF(AND(B19<>"",B19<>"Non trouvé - vérifier",D19<>"",D19<>0),SUMIF($B$2:$B$244,B19,$D$2:$D$244),"") | G19: =IF(AND(B19<>"",B19<>"Non trouvé - vérifier",D19<>"",D19<>0),IF(COUNTIF($B$2:B19,B19)=1,1,0),0) -> 0
A20: Collecteur 2 | B20: =IFERROR(INDEX(Catalogue!$A$4:$A$454,SUMPRODUCT(((Catalogue!$C$4:$C$454="CPC")*(Catalogue!$D$4:$D$454=IF(SPK!$D$4="X","ROUGE",IF(SPK!$F$4="X","GALVA",IF(SPK!$H$4="X","GALVA",""))))*(Catalogue!$F$4:$F$454=(SPK!$F$9+0))*(Catalogue!$E$4:$E$454=(SPK!$F$12+0))*(Catalogue!$G$4:$G$454=IF(LEFT(SPK!$F$13,1)="R","RAINURE",IF(LEFT(SPK!$F$13,1)="T","TARAUDE",""))))*ROW(Catalogue!$C$4:$C$454))-3),"Non trouvé - vérifier") -> Non trouvé - vérifier | C20: =IFERROR(INDEX(Catalogue!$B$4:$B$454,SUMPRODUCT(((Catalogue!$C$4:$C$454="CPC")*(Catalogue!$D$4:$D$454=IF(SPK!$D$4="X","ROUGE",IF(SPK!$F$4="X","GALVA",IF(SPK!$H$4="X","GALVA",""))))*(Catalogue!$F$4:$F$454=(SPK!$F$9+0))*(Catalogue!$E$4:$E$454=(SPK!$F$12+0))*(Catalogue!$G$4:$G$454=IF(LEFT(SPK!$F$13,1)="R","RAINURE",IF(LEFT(SPK!$F$13,1)="T","TARAUDE",""))))*ROW(Catalogue!$C$4:$C$454))-3),"") | D20: =1 -> 1 | E20: pce | F20: =IF(AND(B20<>"",B20<>"Non trouvé - vérifier",D20<>"",D20<>0),SUMIF($B$2:$B$244,B20,$D$2:$D$244),"") | G20: =IF(AND(B20<>"",B20<>"Non trouvé - vérifier",D20<>"",D20<>0),IF(COUNTIF($B$2:B20,B20)=1,1,0),0) -> 0
A21: Collecteur 2 | B21: =IFERROR(INDEX(Catalogue!$A$4:$A$454,SUMPRODUCT(((Catalogue!$C$4:$C$454="RACCORD")*(Catalogue!$D$4:$D$454=IF(SPK!$D$4="X","ROUGE",IF(SPK!$F$4="X","BLANC",IF(SPK!$H$4="X","GALVA",""))))*(Catalogue!$E$4:$E$454=(SPK!$F$9+0)))*ROW(Catalogue!$C$4:$C$454))-3),"Non trouvé - vérifier") -> Non trouvé - vérifier | C21: =IFERROR(INDEX(Catalogue!$B$4:$B$454,SUMPRODUCT(((Catalogue!$C$4:$C$454="RACCORD")*(Catalogue!$D$4:$D$454=IF(SPK!$D$4="X","ROUGE",IF(SPK!$F$4="X","BLANC",IF(SPK!$H$4="X","GALVA",""))))*(Catalogue!$E$4:$E$454=(SPK!$F$9+0)))*ROW(Catalogue!$C$4:$C$454))-3),"") | D21: =ROUNDUP(((SPK!$F$10/6)+(SPK!$F$11*2))*1.1,0) -> 0 | E21: pce | F21: =IF(AND(B21<>"",B21<>"Non trouvé - vérifier",D21<>"",D21<>0),SUMIF($B$2:$B$244,B21,$D$2:$D$244),"") | G21: =IF(AND(B21<>"",B21<>"Non trouvé - vérifier",D21<>"",D21<>0),IF(COUNTIF($B$2:B21,B21)=1,1,0),0) -> 0
A22: Collecteur 2 - Support 1 | B22: =IF((IFERROR(INDEX(Supports!$C$4:$C$23,MATCH(SPK!$F$14,Supports!$B$4:$B$23,0)),""))="","",IF(IFERROR(INDEX(Supports!$C$4:$C$23,MATCH(SPK!$F$14,Supports!$B$4:$B$23,0)),"")="ETRIER RALLONGE (DN automatique = DN du tube)",IFERROR(INDEX(Catalogue!$A$4:$A$454,SUMPRODUCT(((Catalogue!$C$4:$C$454="ETRIER")*(Catalogue!$E$4:$E$454=(SPK!$F$9+0)))*ROW(Catalogue!$C$4:$C$454))-3),"Non trouvé - vérifier"),IF(IFERROR(INDEX(Supports!$C$4:$C$23,MATCH(SPK!$F$14,Supports!$B$4:$B$23,0)),"")="COLLIER INDUSTRIEL (DN automatique = DN du tube)",IFERROR(INDEX(Catalogue!$A$4:$A$454,SUMPRODUCT(((Catalogue!$C$4:$C$454="COLLIERINDUS")*(Catalogue!$E$4:$E$454=(SPK!$F$9+0)))*ROW(Catalogue!$C$4:$C$454))-3),"Non trouvé - vérifier"),IF(IFERROR(INDEX(Supports!$C$4:$C$23,MATCH(SPK!$F$14,Supports!$B$4:$B$23,0)),"")="COLLIER POIRE (DN automatique = DN du tube)",IFERROR(INDEX(Catalogue!$A$4:$A$454,SUMPRODUCT(((Catalogue!$C$4:$C$454="COLLIERPOIRE")*(Catalogue!$E$4:$E$454=(SPK!$F$9+0)))*ROW(Catalogue!$C$4:$C$454))-3),"Non trouvé - vérifier"),IFERROR(INDEX(Catalogue!$A$4:$A$454,MATCH(IFERROR(INDEX(Supports!$C$4:$C$23,MATCH(SPK!$F$14,Supports!$B$4:$B$23,0)),""),Catalogue!$B$4:$B$454,0)),""))))) | C22: =IF((IFERROR(INDEX(Supports!$C$4:$C$23,MATCH(SPK!$F$14,Supports!$B$4:$B$23,0)),""))="","",IF(IFERROR(INDEX(Supports!$C$4:$C$23,MATCH(SPK!$F$14,Supports!$B$4:$B$23,0)),"")="ETRIER RALLONGE (DN automatique = DN du tube)",IFERROR(INDEX(Catalogue!$B$4:$B$454,SUMPRODUCT(((Catalogue!$C$4:$C$454="ETRIER")*(Catalogue!$E$4:$E$454=(SPK!$F$9+0)))*ROW(Catalogue!$C$4:$C$454))-3),""),IF(IFERROR(INDEX(Supports!$C$4:$C$23,MATCH(SPK!$F$14,Supports!$B$4:$B$23,0)),"")="COLLIER INDUSTRIEL (DN automatique = DN du tube)",IFERROR(INDEX(Catalogue!$B$4:$B$454,SUMPRODUCT(((Catalogue!$C$4:$C$454="COLLIERINDUS")*(Catalogue!$E$4:$E$454=(SPK!$F$9+0)))*ROW(Catalogue!$C$4:$C$454))-3),""),IF(IFERROR(INDEX(Supports!$C$4:$C$23,MATCH(SPK!$F$14,Supports!$B$4:$B$23,0)),"")="COLLIER POIRE (DN automatique = DN du tube)",IFERROR(INDEX(Catalogue!$B$4:$B$454,SUMPRODUCT(((Catalogue!$C$4:$C$454="COLLIERPOIRE")*(Catalogue!$E$4:$E$454=(SPK!$F$9+0)))*ROW(Catalogue!$C$4:$C$454))-3),""),IFERROR(INDEX(Supports!$C$4:$C$23,MATCH(SPK!$F$14,Supports!$B$4:$B$23,0)),""))))) | D22: =IF((IFERROR(INDEX(Supports!$C$4:$C$23,MATCH(SPK!$F$14,Supports!$B$4:$B$23,0)),""))="","",(IFERROR(INDEX(Supports!$D$4:$D$23,MATCH(SPK!$F$14,Supports!$B$4:$B$23,0)),0))*SPK!$F$15) | E22: pce/m | F22: =IF(AND(B22<>"",B22<>"Non trouvé - vérifier",D22<>"",D22<>0),SUMIF($B$2:$B$244,B22,$D$2:$D$244),"") | G22: =IF(AND(B22<>"",B22<>"Non trouvé - vérifier",D22<>"",D22<>0),IF(COUNTIF($B$2:B22,B22)=1,1,0),0) -> 0
A23: Collecteur 2 - Support 1 | B23: =IF((IFERROR(INDEX(Supports!$E$4:$E$23,MATCH(SPK!$F$14,Supports!$B$4:$B$23,0)),""))="","",IF(IFERROR(INDEX(Supports!$E$4:$E$23,MATCH(SPK!$F$14,Supports!$B$4:$B$23,0)),"")="ETRIER RALLONGE (DN automatique = DN du tube)",IFERROR(INDEX(Catalogue!$A$4:$A$454,SUMPRODUCT(((Catalogue!$C$4:$C$454="ETRIER")*(Catalogue!$E$4:$E$454=(SPK!$F$9+0)))*ROW(Catalogue!$C$4:$C$454))-3),"Non trouvé - vérifier"),IF(IFERROR(INDEX(Supports!$E$4:$E$23,MATCH(SPK!$F$14,Supports!$B$4:$B$23,0)),"")="COLLIER INDUSTRIEL (DN automatique = DN du tube)",IFERROR(INDEX(Catalogue!$A$4:$A$454,SUMPRODUCT(((Catalogue!$C$4:$C$454="COLLIERINDUS")*(Catalogue!$E$4:$E$454=(SPK!$F$9+0)))*ROW(Catalogue!$C$4:$C$454))-3),"Non trouvé - vérifier"),IF(IFERROR(INDEX(Supports!$E$4:$E$23,MATCH(SPK!$F$14,Supports!$B$4:$B$23,0)),"")="COLLIER POIRE (DN automatique = DN du tube)",IFERROR(INDEX(Catalogue!$A$4:$A$454,SUMPRODUCT(((Catalogue!$C$4:$C$454="COLLIERPOIRE")*(Catalogue!$E$4:$E$454=(SPK!$F$9+0)))*ROW(Catalogue!$C$4:$C$454))-3),"Non trouvé - vérifier"),IFERROR(INDEX(Catalogue!$A$4:$A$454,MATCH(IFERROR(INDEX(Supports!$E$4:$E$23,MATCH(SPK!$F$14,Supports!$B$4:$B$23,0)),""),Catalogue!$B$4:$B$454,0)),""))))) | C23: =IF((IFERROR(INDEX(Supports!$E$4:$E$23,MATCH(SPK!$F$14,Supports!$B$4:$B$23,0)),""))="","",IF(IFERROR(INDEX(Supports!$E$4:$E$23,MATCH(SPK!$F$14,Supports!$B$4:$B$23,0)),"")="ETRIER RALLONGE (DN automatique = DN du tube)",IFERROR(INDEX(Catalogue!$B$4:$B$454,SUMPRODUCT(((Catalogue!$C$4:$C$454="ETRIER")*(Catalogue!$E$4:$E$454=(SPK!$F$9+0)))*ROW(Catalogue!$C$4:$C$454))-3),""),IF(IFERROR(INDEX(Supports!$E$4:$E$23,MATCH(SPK!$F$14,Supports!$B$4:$B$23,0)),"")="COLLIER INDUSTRIEL (DN automatique = DN du tube)",IFERROR(INDEX(Catalogue!$B$4:$B$454,SUMPRODUCT(((Catalogue!$C$4:$C$454="COLLIERINDUS")*(Catalogue!$E$4:$E$454=(SPK!$F$9+0)))*ROW(Catalogue!$C$4:$C$454))-3),""),IF(IFERROR(INDEX(Supports!$E$4:$E$23,MATCH(SPK!$F$14,Supports!$B$4:$B$23,0)),"")="COLLIER POIRE (DN automatique = DN du tube)",IFERROR(INDEX(Catalogue!$B$4:$B$454,SUMPRODUCT(((Catalogue!$C$4:$C$454="COLLIERPOIRE")*(Catalogue!$E$4:$E$454=(SPK!$F$9+0)))*ROW(Catalogue!$C$4:$C$454))-3),""),IFERROR(INDEX(Supports!$E$4:$E$23,MATCH(SPK!$F$14,Supports!$B$4:$B$23,0)),""))))) | D23: =IF((IFERROR(INDEX(Supports!$E$4:$E$23,MATCH(SPK!$F$14,Supports!$B$4:$B$23,0)),""))="","",(IFERROR(INDEX(Supports!$F$4:$F$23,MATCH(SPK!$F$14,Supports!$B$4:$B$23,0)),0))*SPK!$F$15) | E23: pce/m | F23: =IF(AND(B23<>"",B23<>"Non trouvé - vérifier",D23<>"",D23<>0),SUMIF($B$2:$B$244,B23,$D$2:$D$244),"") | G23: =IF(AND(B23<>"",B23<>"Non trouvé - vérifier",D23<>"",D23<>0),IF(COUNTIF($B$2:B23,B23)=1,1,0),0) -> 0
A24: Collecteur 2 - Support 1 | B24: =IF((IFERROR(INDEX(Supports!$G$4:$G$23,MATCH(SPK!$F$14,Supports!$B$4:$B$23,0)),""))="","",IF(IFERROR(INDEX(Supports!$G$4:$G$23,MATCH(SPK!$F$14,Supports!$B$4:$B$23,0)),"")="ETRIER RALLONGE (DN automatique = DN du tube)",IFERROR(INDEX(Catalogue!$A$4:$A$454,SUMPRODUCT(((Catalogue!$C$4:$C$454="ETRIER")*(Catalogue!$E$4:$E$454=(SPK!$F$9+0)))*ROW(Catalogue!$C$4:$C$454))-3),"Non trouvé - vérifier"),IF(IFERROR(INDEX(Supports!$G$4:$G$23,MATCH(SPK!$F$14,Supports!$B$4:$B$23,0)),"")="COLLIER INDUSTRIEL (DN automatique = DN du tube)",IFERROR(INDEX(Catalogue!$A$4:$A$454,SUMPRODUCT(((Catalogue!$C$4:$C$454="COLLIERINDUS")*(Catalogue!$E$4:$E$454=(SPK!$F$9+0)))*ROW(Catalogue!$C$4:$C$454))-3),"Non trouvé - vérifier"),IF(IFERROR(INDEX(Supports!$G$4:$G$23,MATCH(SPK!$F$14,Supports!$B$4:$B$23,0)),"")="COLLIER POIRE (DN automatique = DN du tube)",IFERROR(INDEX(Catalogue!$A$4:$A$454,SUMPRODUCT(((Catalogue!$C$4:$C$454="COLLIERPOIRE")*(Catalogue!$E$4:$E$454=(SPK!$F$9+0)))*ROW(Catalogue!$C$4:$C$454))-3),"Non trouvé - vérifier"),IFERROR(INDEX(Catalogue!$A$4:$A$454,MATCH(IFERROR(INDEX(Supports!$G$4:$G$23,MATCH(SPK!$F$14,Supports!$B$4:$B$23,0)),""),Catalogue!$B$4:$B$454,0)),""))))) | C24: =IF((IFERROR(INDEX(Supports!$G$4:$G$23,MATCH(SPK!$F$14,Supports!$B$4:$B$23,0)),""))="","",IF(IFERROR(INDEX(Supports!$G$4:$G$23,MATCH(SPK!$F$14,Supports!$B$4:$B$23,0)),"")="ETRIER RALLONGE (DN automatique = DN du tube)",IFERROR(INDEX(Catalogue!$B$4:$B$454,SUMPRODUCT(((Catalogue!$C$4:$C$454="ETRIER")*(Catalogue!$E$4:$E$454=(SPK!$F$9+0)))*ROW(Catalogue!$C$4:$C$454))-3),""),IF(IFERROR(INDEX(Supports!$G$4:$G$23,MATCH(SPK!$F$14,Supports!$B$4:$B$23,0)),"")="COLLIER INDUSTRIEL (DN automatique = DN du tube)",IFERROR(INDEX(Catalogue!$B$4:$B$454,SUMPRODUCT(((Catalogue!$C$4:$C$454="COLLIERINDUS")*(Catalogue!$E$4:$E$454=(SPK!$F$9+0)))*ROW(Catalogue!$C$4:$C$454))-3),""),IF(IFERROR(INDEX(Supports!$G$4:$G$23,MATCH(SPK!$F$14,Supports!$B$4:$B$23,0)),"")="COLLIER POIRE (DN automatique = DN du tube)",IFERROR(INDEX(Catalogue!$B$4:$B$454,SUMPRODUCT(((Catalogue!$C$4:$C$454="COLLIERPOIRE")*(Catalogue!$E$4:$E$454=(SPK!$F$9+0)))*ROW(Catalogue!$C$4:$C$454))-3),""),IFERROR(INDEX(Supports!$G$4:$G$23,MATCH(SPK!$F$14,Supports!$B$4:$B$23,0)),""))))) | D24: =IF((IFERROR(INDEX(Supports!$G$4:$G$23,MATCH(SPK!$F$14,Supports!$B$4:$B$23,0)),""))="","",(IFERROR(INDEX(Supports!$H$4:$H$23,MATCH(SPK!$F$14,Supports!$B$4:$B$23,0)),0))*SPK!$F$15) | E24: pce/m | F24: =IF(AND(B24<>"",B24<>"Non trouvé - vérifier",D24<>"",D24<>0),SUMIF($B$2:$B$244,B24,$D$2:$D$244),"") | G24: =IF(AND(B24<>"",B24<>"Non trouvé - vérifier",D24<>"",D24<>0),IF(COUNTIF($B$2:B24,B24)=1,1,0),0) -> 0
